원문: https://ko.javascript.info/task/then-vs-catch

<details>
  <summary>정답</summary>

  위 코드는 f1 내에서 에러가 발생해도 catch해 f2를 실행시키지만

  아래 코드는 f1 내에서 에러 발생 시 에러를 처리하지 못한다.
</details>
